[2020-04-28 18:27:10,738] {alignmentservice.py:242} MainThread INFO in alignmentservice: Consumer running.......
[2020-04-28 18:28:37,761] {alignmentservice.py:243} MainThread INFO in alignmentservice: Consumer running.......
[2020-04-28 18:35:00,032] {alignmentservice.py:252} MainThread INFO in alignmentservice: Consumer running.......
[2020-04-28 18:45:51,961] {consumer.py:252} MainThread INFO in consumer: Consumer running.......
[2020-04-28 19:14:59,527] {consumer.py:33} MainThread INFO in consumer: Consumer running.......
[2020-05-08 13:42:25,392] {consumer.py:35} MainThread INFO in consumer: Consumer running.......
[2020-05-08 13:52:36,359] {consumer.py:39} MainThread INFO in consumer: Consuming from the Kafka Queue......
[2020-05-08 13:54:41,090] {alignmentservice.py:50} MainThread INFO in alignmentservice: Alignment process starts for job: 15889250265440123
[2020-05-08 13:54:41,101] {consumer.py:44} MainThread ERROR in consumer: Exception while consuming: can only concatenate str (not "dict") to str
[2020-05-08 13:54:41,121] {consumer.py:45} MainThread ERROR in consumer: None
[2020-06-18 12:33:40,850] {_internal.py:113} MainThread INFO in _internal:  * Running on http://0.0.0.0:5002/ (Press CTRL+C to quit)
[2020-06-24 14:55:10,979] {_internal.py:113} MainThread INFO in _internal:  * Running on http://0.0.0.0:5003/ (Press CTRL+C to quit)
[2020-06-24 14:57:09,083] {_internal.py:113} MainThread INFO in _internal:  * Running on http://0.0.0.0:5003/ (Press CTRL+C to quit)
[2020-06-24 14:57:49,924] {_internal.py:113} MainThread INFO in _internal:  * Running on http://0.0.0.0:5003/ (Press CTRL+C to quit)
[2020-06-24 14:59:01,687] {_internal.py:113} MainThread INFO in _internal:  * Running on http://0.0.0.0:5003/ (Press CTRL+C to quit)
[2020-06-24 15:00:13,954] {app.py:29} MainThread INFO in app: Starting
[2020-06-24 15:00:13,955] {alignmentconsumer.py:40} AlignerKafka-Thread INFO in alignmentconsumer: Consumer
[2020-06-24 15:00:14,807] {_internal.py:113} MainThread INFO in _internal:  * Running on http://0.0.0.0:5003/ (Press CTRL+C to quit)
[2020-06-24 15:02:29,647] {app.py:29} MainThread INFO in app: Starting
[2020-06-24 15:02:30,511] {_internal.py:113} MainThread INFO in _internal:  * Running on http://0.0.0.0:5003/ (Press CTRL+C to quit)
[2020-06-24 15:03:25,030] {app.py:29} MainThread INFO in app: Starting
[2020-06-24 15:03:25,035] {alignmentconsumer.py:42} AlignerKafka-Thread INFO in alignmentconsumer: Consumer running.......
[2020-06-24 15:03:25,883] {_internal.py:113} MainThread INFO in _internal:  * Running on http://0.0.0.0:5003/ (Press CTRL+C to quit)
[2020-06-24 15:04:38,075] {_internal.py:113} MainThread INFO in _internal:  * Running on http://0.0.0.0:5003/ (Press CTRL+C to quit)
[2020-06-24 15:04:55,103] {alignmentconsumer.py:42} AlignerKafka-Thread INFO in alignmentconsumer: Consumer running.......
[2020-06-24 15:05:33,022] {_internal.py:113} MainThread INFO in _internal:  * Running on http://0.0.0.0:5003/ (Press CTRL+C to quit)
[2020-06-24 15:05:56,558] {alignmentconsumer.py:42} AlignerKafka-Thread INFO in alignmentconsumer: Consumer running.......
[2020-07-01 13:08:59,444] {alignmentconsumer.py:42} AlignerKafka-Thread INFO in alignmentconsumer: Consumer running.......
[2020-07-01 13:09:00,461] {_internal.py:113} MainThread INFO in _internal:  * Running on http://0.0.0.0:5003/ (Press CTRL+C to quit)
[2020-07-10 14:47:12,230] {alignmentconsumer.py:38} AlignerConsumer-Thread INFO in alignmentconsumer: Align Consumer running.......
[2020-07-10 14:47:12,232] {alignmentwflowconsumer.py:38} AlignerWflowConsumer-Thread INFO in alignmentwflowconsumer: Align WFM Consumer running.......
[2020-07-10 14:47:13,230] {_internal.py:113} MainThread INFO in _internal:  * Running on http://0.0.0.0:5003/ (Press CTRL+C to quit)
[2020-07-10 14:48:56,730] {app.py:1892} Thread-1 ERROR in app: Exception on /anuvaad-etl/extractor/aligner/v1/sentences/align [POST]
Traceback (most recent call last):
  File "C:\Users\Vishal\AppData\Local\Programs\Python\Python37\lib\site-packages\flask\app.py", line 2447, in wsgi_app
    response = self.full_dispatch_request()
  File "C:\Users\Vishal\AppData\Local\Programs\Python\Python37\lib\site-packages\flask\app.py", line 1952, in full_dispatch_request
    rv = self.handle_user_exception(e)
  File "C:\Users\Vishal\AppData\Local\Programs\Python\Python37\lib\site-packages\flask\app.py", line 1821, in handle_user_exception
    reraise(exc_type, exc_value, tb)
  File "C:\Users\Vishal\AppData\Local\Programs\Python\Python37\lib\site-packages\flask\_compat.py", line 39, in reraise
    raise value
  File "C:\Users\Vishal\AppData\Local\Programs\Python\Python37\lib\site-packages\flask\app.py", line 1950, in full_dispatch_request
    rv = self.dispatch_request()
  File "C:\Users\Vishal\AppData\Local\Programs\Python\Python37\lib\site-packages\flask\app.py", line 1936, in dispatch_request
    return self.view_functions[rule.endpoint](**req.view_args)
  File "C:\Users\Vishal\Desktop\new-repo\anuvaad\anuvaad-etl\anuvaad-extractor\aligner\etl-aligner\controller\alignmentcontroller.py", line 21, in createalignmentjob
    error = validator.validate_input(data)
  File "C:\Users\Vishal\Desktop\new-repo\anuvaad\anuvaad-etl\anuvaad-extractor\aligner\etl-aligner\validator\alignmentvalidator.py", line 25, in validate_input
    return post_error("TARGET_NOT_FOUND", "Details of the target not available", None)
  File "C:\Users\Vishal\Desktop\new-repo\anuvaad\anuvaad-etl\anuvaad-extractor\aligner\etl-aligner\error_manager\emservice.py", line 20, in post_error
    index_to_es(error)
TypeError: index_to_es() missing 1 required positional argument: 'index_obj'
[2020-07-10 14:48:56,820] {_internal.py:113} Thread-1 INFO in _internal: 127.0.0.1 - - [10/Jul/2020 14:48:56] "[35m[1mPOST /anuvaad-etl/extractor/aligner/v1/sentences/align HTTP/1.1[0m" 500 -
[2020-07-10 14:50:50,241] {alignmentconsumer.py:38} AlignerConsumer-Thread INFO in alignmentconsumer: Align Consumer running.......
[2020-07-10 14:50:50,249] {alignmentwflowconsumer.py:38} AlignerWflowConsumer-Thread INFO in alignmentwflowconsumer: Align WFM Consumer running.......
[2020-07-10 14:50:51,116] {_internal.py:113} MainThread INFO in _internal:  * Running on http://0.0.0.0:5003/ (Press CTRL+C to quit)
[2020-07-10 14:50:57,157] {eswrapper.py:29} Thread-1 ERROR in eswrapper: Indexing FAILED for errorID: error-15943728571560373
Traceback (most recent call last):
  File "C:\Users\Vishal\Desktop\new-repo\anuvaad\anuvaad-etl\anuvaad-extractor\aligner\etl-aligner\error_manager\eswrapper.py", line 27, in index_to_es
    es.index(index=es_error_index_test, type=in_type, id=id, body=index_obj)
  File "C:\Users\Vishal\AppData\Local\Programs\Python\Python37\lib\site-packages\elasticsearch\client\utils.py", line 139, in _wrapped
    return func(*args, params=params, headers=headers, **kwargs)
TypeError: index() got an unexpected keyword argument 'type'
[2020-07-10 14:50:57,202] {_internal.py:113} Thread-1 INFO in _internal: 127.0.0.1 - - [10/Jul/2020 14:50:57] "[37mPOST /anuvaad-etl/extractor/aligner/v1/sentences/align HTTP/1.1[0m" 200 -
